<?xml version="1.0" encoding="utf-8"?>
<robot name="njust_v2_fixed">

    <material name="black">
        <color rgba="0.0 0.0 0.0 1.0"/>
    </material>
    <material name="blue">
        <color rgba="0.0 0.0 0.8 1.0"/>
    </material>
    <material name="green">
        <color rgba="0.0 0.8 0.0 1.0"/>
    </material>
    <material name="grey">
        <color rgba="0.2 0.2 0.2 1.0"/>
    </material>
    <material name="silver">
        <color rgba="0.9137254901960784 0.9137254901960784 0.8470588235294118 1.0"/>
    </material>
    <material name="orange">
        <color rgba="1.0 0.4235294117647059 0.0392156862745098 1.0"/>
    </material>
    <material name="brown">
        <color rgba="0.8705882352941177 0.8117647058823529 0.7647058823529411 1.0"/>
    </material>
    <material name="red">
        <color rgba="0.8 0.0 0.0 1.0"/>
    </material>
    <material name="white">
        <color rgba="1.0 1.0 1.0 1.0"/>
    </material>

    <link name="base">
        <visual>
            <origin rpy="0 0 0" xyz="0 0 0"/>
            <geometry>
                <box size="0.001 0.001 0.001"/>
            </geometry>
        </visual>
    </link>
    <joint name="floating_base" type="fixed">
        <origin rpy="0 0 0" xyz="0 0 0"/>
        <parent link="base"/>
        <child link="trunk"/>
    </joint>
    <link name="trunk">
        <visual>
            <origin rpy="0 0 0" xyz="0 0 0"/>
            <geometry>
                <mesh filename="../meshes/base_link.STL" scale="1 1 1"/>
            </geometry>
            <material name="orange"/>
        </visual>
        <collision>
            <origin rpy="0 0 0" xyz="0 0 0"/>
            <geometry>
                <mesh filename="../meshes/base_link.STL" scale="1 1 1"/>
            </geometry>
            <material name="orange"/>
        </collision>
        <!-- <collision>
            <geometry>
            <box size="0.234 0.184 0.08"/>
            </geometry>
        </collision> -->
        <inertial>
            <origin rpy="0 0 0" xyz="0 0 0"/>
            <mass value="22.002"/>
            <inertia ixx="0.36727" ixy="0.000499" ixz="0.001511" iyy="0.58761" iyz="0.0028" izz="0.83428"/>
        </inertial>
    </link>
    <joint name="imu_joint" type="fixed">
        <parent link="trunk"/>
        <child link="imu_link"/>
        <origin rpy="0 0 0" xyz="0 0 0"/>
    </joint>
    <link name="imu_link">
        <inertial>
            <mass value="0.001"/>
            <origin rpy="0 0 0" xyz="0 0 0"/>
            <inertia ixx="0.0001" ixy="0" ixz="0" iyy="0.0001" iyz="0" izz="0.0001"/>
        </inertial>
        <visual>
            <origin rpy="0 0 0" xyz="0 0 0"/>
            <geometry>
                <box size="0.001 0.001 0.001"/>
            </geometry>
            <material name="red"/>
        </visual>
        <collision>
            <origin rpy="0 0 0" xyz="0 0 0"/>
            <geometry>
                <box size=".001 .001 .001"/>
            </geometry>
        </collision>
    </link>

    <link name="FR_hip">
        <inertial>
            <origin rpy="0 0 0" xyz="0 0 0"/>
            <mass value="1.9984"/>
            <inertia ixx="0.003256" ixy="1E-05" ixz="6E-06" iyy="0.005207" iyz="1.8E-05" izz="0.004451"/>
        </inertial>
        <visual>
            <origin rpy="0 0 0" xyz="0 0 0"/>
            <geometry>
                <mesh filename="../meshes/FR_hip.STL"/>
            </geometry>
            <material name="">
                <color rgba="0.79608 0.82353 0.93725 1"/>
            </material>
        </visual>
        <collision>
            <origin rpy="0 0 0" xyz="0 0 0"/>
            <geometry>
                <mesh filename="../meshes/FR_hip.STL"/>
            </geometry>
        </collision>
    </link>
    <joint name="FR_hip_joint" type="revolute">
        <origin rpy="0 0 0" xyz="0.29 -0.125 0"/>
        <parent link="trunk"/>
        <child link="FR_hip"/>
        <axis xyz="1 0 0"/>
        <limit effort="120" lower="-2.0943951023931953" upper="2.0943951023931953" velocity="10"/>
    </joint>
    <link name="FR_thigh">
        <inertial>
            <origin rpy="0 0 0" xyz="0 0 0"/>
            <mass value="2.375"/>
            <inertia ixx="0.017933" ixy="1.2E-05" ixz="0.002123" iyy="0.014218" iyz="5E-06" izz="0.009414"/>
        </inertial>
        <visual>
            <origin rpy="0 0 0" xyz="0 0 0"/>
            <geometry>
                <mesh filename="../meshes/FR_thigh.STL"/>
            </geometry>
            <material name="">
                <color rgba="0.79608 0.82353 0.93725 1"/>
            </material>
        </visual>
        <collision>
            <origin rpy="0 0 0" xyz="0 0 0"/>
            <geometry>
                <mesh filename="../meshes/FR_thigh.STL"/>
            </geometry>
        </collision>
    </link>
    <joint name="FR_thigh_joint" type="revolute">
        <origin rpy="0 0 0" xyz="0 -0.1115 0"/>
        <parent link="FR_hip"/>
        <child link="FR_thigh"/>
        <axis xyz="0 1 0"/>
        <limit effort="120" lower="-3.490658503988659" upper="0.3490658503988659" velocity="10"/>
    </joint>
    <link name="FR_calf">
        <inertial>
            <origin rpy="0 0 0" xyz="0 0 0"/>
            <mass value="0.66013"/>
            <inertia ixx="0.020461" ixy="5E-06" ixz="0.001151" iyy="0.020648" iyz="0.000173" izz="0.000334"/>
        </inertial>
        <visual>
            <origin rpy="0 0 0" xyz="0 0 0"/>
            <geometry>
                <mesh filename="../meshes/FR_calf.STL"/>
            </geometry>
            <material name="">
                <color rgba="0.79608 0.82353 0.93725 1"/>
            </material>
        </visual>
        <collision>
            <origin rpy="0 0 0" xyz="0 0 0"/>
            <geometry>
                <mesh filename="../meshes/FR_calf.STL"/>
            </geometry>
        </collision>
    </link>
    <joint name="FR_calf_joint" type="revolute">
        <origin rpy="0 0 0" xyz="0.040673 0 -0.2568"/>
        <parent link="FR_thigh"/>
        <child link="FR_calf"/>
        <axis xyz="0 1 0"/>
        <limit effort="120" lower="0.4363323129985824" upper="2.7576202181510405" velocity="10"/>
    </joint>
    <link name="FR_wheel">
        <inertial>
            <origin rpy="0 0 0" xyz="0 0 0"/>
            <mass value="2.4127"/>
            <inertia ixx="0.006334" ixy="0" ixz="0" iyy="0.011762" iyz="0" izz="0.006334"/>
        </inertial>
        <visual>
            <origin rpy="0 0 0" xyz="0 0 0"/>
            <geometry>
                <mesh filename="../meshes/FR_wheel.STL"/>
            </geometry>
            <material name="">
                <color rgba="0.79608 0.82353 0.93725 1"/>
            </material>
        </visual>
        <collision>
            <origin rpy="0 0 0" xyz="0 0 0"/>
            <geometry>
                <mesh filename="../meshes/FR_wheel.STL"/>
            </geometry>
        </collision>
    </link>
    <joint name="FR_wheel_joint" type="fixed" dont_collapse="true">
        <origin rpy="0 0 0" xyz="0.039618 -0.047304 -0.28534"/>
        <parent link="FR_calf"/>
        <child link="FR_wheel"/>
    </joint>
    <link name="FL_hip">
        <inertial>
            <origin rpy="0 0 0" xyz="0 0 0"/>
            <mass value="1.9984"/>
            <inertia ixx="0.003256" ixy="1E-05" ixz="6E-06" iyy="0.005207" iyz="1.8E-05" izz="0.004451"/>
        </inertial>
        <visual>
            <origin rpy="0 0 0" xyz="0 0 0"/>
            <geometry>
                <mesh filename="../meshes/FL_hip.STL"/>
            </geometry>
            <material name="">
                <color rgba="0.79608 0.82353 0.93725 1"/>
            </material>
        </visual>
        <collision>
            <origin rpy="0 0 0" xyz="0 0 0"/>
            <geometry>
                <mesh filename="../meshes/FL_hip.STL"/>
            </geometry>
        </collision>
    </link>

    <joint name="FL_hip_joint" type="revolute">
        <origin rpy="0 0 0" xyz="0.29 0.125 0"/>
        <parent link="trunk"/>
        <child link="FL_hip"/>
        <axis xyz="1 0 0"/>
        <limit effort="120" lower="-2.0943951023931953" upper="2.0943951023931953" velocity="10"/>
    </joint>
    <link name="FL_thigh">
        <inertial>
            <origin rpy="0 0 0" xyz="0 0 0"/>
            <mass value="2.375"/>
            <inertia ixx="0.01793" ixy="1E-06" ixz="0.002121" iyy="0.014218" iyz="1E-05" izz="0.009417"/>
        </inertial>
        <visual>
            <origin rpy="0 0 0" xyz="0 0 0"/>
            <geometry>
                <mesh filename="../meshes/FL_thigh.STL"/>
            </geometry>
            <material name="">
                <color rgba="1 1 1 1"/>
            </material>
        </visual>
        <collision>
            <origin rpy="0 0 0" xyz="0 0 0"/>
            <geometry>
                <mesh filename="../meshes/FL_thigh.STL"/>
            </geometry>
        </collision>
    </link>
    <joint name="FL_thigh_joint" type="revolute">
        <origin rpy="0 0 0" xyz="0 0.1115 0"/>
        <parent link="FL_hip"/>
        <child link="FL_thigh"/>
        <axis xyz="0 1 0"/>
        <limit effort="120" lower="-3.490658503988659" upper="0.3490658503988659" velocity="10"/>
    </joint>
    <link name="FL_calf">
        <inertial>
            <origin rpy="0 0 0" xyz="0 0 0"/>
            <mass value="0.66013"/>
            <inertia ixx="0.020458" ixy="1.9E-05" ixz="0.001151" iyy="0.020648" iyz="0.000142" izz="0.000331"/>
        </inertial>
        <visual>
            <origin rpy="0 0 0" xyz="0 0 0"/>
            <geometry>
                <mesh filename="../meshes/FL_calf.STL"/>
            </geometry>
            <material name="">
                <color rgba="1 1 1 1"/>
            </material>
        </visual>
        <collision>
            <origin rpy="0 0 0" xyz="0 0 0"/>
            <geometry>
                <mesh filename="../meshes/FL_calf.STL"/>
            </geometry>
        </collision>
    </link>
    <joint name="FL_calf_joint" type="revolute">
        <origin rpy="0 0 0" xyz="0.040673 0 -0.2568"/>
        <parent link="FL_thigh"/>
        <child link="FL_calf"/>
        <axis xyz="0 1 0"/>
        <limit effort="120" lower="0.4363323129985824" upper="2.7576202181510405" velocity="10"/>
    </joint>
    <link name="FL_wheel">
        <inertial>
            <origin rpy="0 0 0" xyz="0 0 0"/>
            <mass value="2.4127"/>
            <inertia ixx="0.006334" ixy="0" ixz="0" iyy="0.011762" iyz="0" izz="0.006334"/>
        </inertial>
        <visual>
            <origin rpy="0 0 0" xyz="0 0 0"/>
            <geometry>
                <mesh filename="../meshes/FL_wheel.STL"/>
            </geometry>
            <material name="">
                <color rgba="0.79608 0.82353 0.93725 1"/>
            </material>
        </visual>
        <collision>
            <origin rpy="0 0 0" xyz="0 0 0"/>
            <geometry>
                <mesh filename="../meshes/FL_wheel.STL"/>
            </geometry>
        </collision>
    </link>
    <joint name="FL_wheel_joint" type="fixed" dont_collapse="true">
        <origin rpy="0 0 0" xyz="0.039618 0.0505 -0.28534"/>
        <parent link="FL_calf"/>
        <child link="FL_wheel"/>
    </joint>

    <link name="RR_hip">
        <inertial>
            <origin rpy="0 0 0" xyz="0 0 0"/>
            <mass value="1.9984"/>
            <inertia ixx="0.003256" ixy="1E-05" ixz="6E-06" iyy="0.005207" iyz="1.8E-05" izz="0.004451"/>
        </inertial>
        <visual>
            <origin rpy="0 0 0" xyz="0 0 0"/>
            <geometry>
                <mesh filename="../meshes/RR_hip.STL"/>
            </geometry>
            <material name="">
                <color rgba="0.79608 0.82353 0.93725 1"/>
            </material>
        </visual>
        <collision>
            <origin rpy="0 0 0" xyz="0 0 0"/>
            <geometry>
                <mesh filename="../meshes/RR_hip.STL"/>
            </geometry>
        </collision>
    </link>
    <joint name="RR_hip_joint" type="revolute">
        <origin rpy="0 0 0" xyz="-0.29 -0.125 0"/>
        <parent link="trunk"/>
        <child link="RR_hip"/>
        <axis xyz="1 0 0"/>
        <limit effort="120" lower="-2.0943951023931953" upper="2.0943951023931953" velocity="10"/>
    </joint>
    <link name="RR_thigh">
        <inertial>
            <origin rpy="0 0 0" xyz="0 0 0"/>
            <mass value="2.375"/>
            <inertia ixx="0.01793" ixy="1E-06" ixz="0.002121" iyy="0.014218" iyz="1E-05" izz="0.009417"/>
        </inertial>
        <visual>
            <origin rpy="0 0 0" xyz="0 0 0"/>
            <geometry>
                <mesh filename="../meshes/RR_thigh.STL"/>
            </geometry>
            <material name="">
                <color rgba="1 1 1 1"/>
            </material>
        </visual>
        <collision>
            <origin rpy="0 0 0" xyz="0 0 0"/>
            <geometry>
                <mesh filename="../meshes/RR_thigh.STL"/>
            </geometry>
        </collision>
    </link>
    <joint name="RR_thigh_joint" type="revolute">
        <origin rpy="0 0 0" xyz="0 -0.1115 0"/>
        <parent link="RR_hip"/>
        <child link="RR_thigh"/>
        <axis xyz="0 1 0"/>
        <limit effort="120" lower="-0.3490658503988659" upper="3.490658503988659" velocity="10"/>
    </joint>
    <link name="RR_calf">
        <inertial>
            <origin rpy="0 0 0" xyz="0 0 0"/>
            <mass value="0.66013"/>
            <inertia ixx="0.020458" ixy="1.9E-05" ixz="0.001151" iyy="0.020648" iyz="0.000142" izz="0.000331"/>
        </inertial>
        <visual>
            <origin rpy="0 0 0" xyz="0 0 0"/>
            <geometry>
                <mesh filename="../meshes/RR_calf.STL"/>
            </geometry>
            <material name="">
                <color rgba="1 1 1 1"/>
            </material>
        </visual>
        <collision>
            <origin rpy="0 0 0" xyz="0 0 0"/>
            <geometry>
                <mesh filename="../meshes/RR_calf.STL"/>
            </geometry>
        </collision>
    </link>
    <joint name="RR_calf_joint" type="revolute">
        <origin rpy="0 0 0" xyz="-0.040673 0 -0.2568"/>
        <parent link="RR_thigh"/>
        <child link="RR_calf"/>
        <axis xyz="0 1 0"/>
        <limit effort="120" lower="-2.7576202181510405" upper="-0.4363323129985824" velocity="10"/>
    </joint>
    <link name="RR_wheel">
        <inertial>
            <origin rpy="0 0 0" xyz="0 0 0"/>
            <mass value="2.4127"/>
            <inertia ixx="0.006334" ixy="0" ixz="0" iyy="0.011762" iyz="0" izz="0.006334"/>
        </inertial>
        <visual>
            <origin rpy="0 0 0" xyz="0 0 0"/>
            <geometry>
                <mesh filename="../meshes/RR_wheel.STL"/>
            </geometry>
            <material name="">
                <color rgba="0.79608 0.82353 0.93725 1"/>
            </material>
        </visual>
        <collision>
            <origin rpy="0 0 0" xyz="0 0 0"/>
            <geometry>
                <mesh filename="../meshes/RR_wheel.STL"/>
            </geometry>
        </collision>
    </link>
    <joint name="RR_wheel_joint" type="fixed" dont_collapse="true">
        <origin rpy="0 0 0" xyz="-0.039618 -0.0505 -0.28534"/>
        <parent link="RR_calf"/>
        <child link="RR_wheel"/>
    </joint>

    <link name="RL_hip">
        <inertial>
            <origin rpy="0 0 0" xyz="0 0 0"/>
            <mass value="1.9984"/>
            <inertia ixx="0.003256" ixy="1E-05" ixz="6E-06" iyy="0.005207" iyz="1.8E-05" izz="0.004451"/>
        </inertial>
        <visual>
            <origin rpy="0 0 0" xyz="0 0 0"/>
            <geometry>
                <mesh filename="../meshes/RL_hip.STL"/>
            </geometry>
            <material name="">
                <color rgba="1 1 1 1"/>
            </material>
        </visual>
        <collision>
            <origin rpy="0 0 0" xyz="0 0 0"/>
            <geometry>
                <mesh filename="../meshes/RL_hip.STL"/>
            </geometry>
        </collision>
    </link>
    <joint name="RL_hip_joint" type="revolute">
        <origin rpy="0 0 0" xyz="-0.29 0.125 0"/>
        <parent link="trunk"/>
        <child link="RL_hip"/>
        <axis xyz="1 0 0"/>
        <limit effort="120" lower="-2.0943951023931953" upper="2.0943951023931953" velocity="10"/>
    </joint>
    <link name="RL_thigh">
        <inertial>
            <origin rpy="0 0 0" xyz="0 0 0"/>
            <mass value="2.375"/>
            <inertia ixx="0.017933" ixy="1.2E-05" ixz="0.002123" iyy="0.014218" iyz="5E-06" izz="0.009414"/>
        </inertial>
        <visual>
            <origin rpy="0 0 0" xyz="0 0 0"/>
            <geometry>
                <mesh filename="../meshes/RL_thigh.STL"/>
            </geometry>
            <material name="">
                <color rgba="0.79608 0.82353 0.93725 1"/>
            </material>
        </visual>
        <collision>
            <origin rpy="0 0 0" xyz="0 0 0"/>
            <geometry>
                <mesh filename="../meshes/RL_thigh.STL"/>
            </geometry>
        </collision>
    </link>
    <joint name="RL_thigh_joint" type="revolute">
        <origin rpy="0 0 0" xyz="0 0.1115 0"/>
        <parent link="RL_hip"/>
        <child link="RL_thigh"/>
        <axis xyz="0 1 0"/>
        <limit effort="120" lower="-0.3490658503988659" upper="3.490658503988659" velocity="10"/>
    </joint>
    <link name="RL_calf">
        <inertial>
            <origin rpy="0 0 0" xyz="0 0 0"/>
            <mass value="0.66013"/>
            <inertia ixx="0.020461" ixy="5E-06" ixz="0.001151" iyy="0.020648" iyz="0.000173" izz="0.000334"/>
        </inertial>
        <visual>
            <origin rpy="0 0 0" xyz="0 0 0"/>
            <geometry>
                <mesh filename="../meshes/RL_calf.STL"/>
            </geometry>
            <material name="">
                <color rgba="0.79608 0.82353 0.93725 1"/>
            </material>
        </visual>
        <collision>
            <origin rpy="0 0 0" xyz="0 0 0"/>
            <geometry>
                <mesh filename="../meshes/RL_calf.STL"/>
            </geometry>
        </collision>
    </link>
    <joint name="RL_calf_joint" type="revolute">
        <origin rpy="0 0 0" xyz="-0.040673 0 -0.2568"/>
        <parent link="RL_thigh"/>
        <child link="RL_calf"/>
        <axis xyz="0 1 0"/>
        <limit effort="120" lower="-2.7576202181510405" upper="-0.4363323129985824" velocity="10"/>
    </joint>
    <link name="RL_wheel">
        <inertial>
            <origin rpy="0 0 0" xyz="0 0 0"/>
            <mass value="2.4127"/>
            <inertia ixx="0.006334" ixy="0" ixz="0" iyy="0.011762" iyz="0" izz="0.006334"/>
        </inertial>
        <visual>
            <origin rpy="0 0 0" xyz="0 0 0"/>
            <geometry>
                <mesh filename="../meshes/RL_wheel.STL"/>
            </geometry>
            <material name="">
                <color rgba="0.79608 0.82353 0.93725 1"/>
            </material>
        </visual>
        <collision>
            <origin rpy="0 0 0" xyz="0 0 0"/>
            <geometry>
                <mesh filename="../meshes/RL_wheel.STL"/>
            </geometry>
        </collision>
    </link>
    <joint name="RL_wheel_joint" type="fixed" dont_collapse="true">
        <origin rpy="0 0 0" xyz="-0.039618 0.047304 -0.28534"/>
        <parent link="RL_calf"/>
        <child link="RL_wheel"/>
    </joint>

</robot>
